Workbook

Sheet Raw_Data
A1: order_id | B1: order_date | C1: customer_id | D1: product_category | E1: region | F1: quantity | G1: unit_price | H1: discount | I1: payment_method | J1: delivery_days | K1: customer_rating | L1: revenue
A2: 10001 | B2: 44562 | C2: 1102 | D2: Beauty | E2: South | F2: 7 | G2: 373.65 | H2: 0.28 | I2: Wallet | J2: 10 | K2: 4.7 | L2: 1883.2
A3: 10002 | B3: 44563 | C3: 1435 | D3: Clothing | E3: South | F3: 7 | G3: 47.74 | H3: 0.09 | I3: Card | J3: 6 | K3: 3.9 | L3: 304.1
A4: 10003 | B4: 44564 | C4: 1860 | D4: Beauty | E4: East | F4: 3 | G4: 311.28 | H4: 0.31 | I4: COD | J4: 6 | K4: 2.5 | L4: 644.35
A5: 10004 | B5: 44565 | C5: 1270 | D5: Electronics | E5: West | F5: 5 | G5: 524.47 | H5: 0.02 | I5: Wallet | J5: 6 | K5: 1.6 | L5: 2569.9
A6: 10005 | B6: 44566 | C6: 1106 | D6: Clothing | E6: West | F6: 5 | G6: 139.87 | H6: 0.33 | I6: Wallet | J6: 4 | K6: 4.9 | L6: 468.56
A7: 10006 | B7: 44567 | C7: 1071 | D7: Electronics | E7: West | F7: 2 | G7: 264.44 | H7: 0.2 | I7: Card | J7: 3 | K7: 3.3 | L7: 423.1
A8: 10007 | B8: 44568 | C8: 1700 | D8: Clothing | E8: South | F8: 6 | G8: 564.6 | H8: 0.23 | I8: Card | J8: 1 | K8: 1.8 | L8: 2608.45
A9: 10008 | B9: 44569 | C9: 1020 | D9: Beauty | E9: North | F9: 6 | G9: 265.71 | H9: 0.13 | I9: Card | J9: 2 | K9: 3.7 | L9: 1387.01
A10: 10009 | B10: 44570 | C10: 1614 | D10: Clothing | E10: South | F10: 6 | G10: 224.65 | H10: 0.27 | I10: Card | J10: 2 | K10: 1.4 | L10: 983.97
A11: 10010 | B11: 44571 | C11: 1121 | D11: Clothing | E11: West | F11: 4 | G11: 272.71 | H11: 0.06 | I11: Card | J11: 10 | K11: 4.5 | L11: 1025.39
A12: 10011 | B12: 44572 | C12: 1466 | D12: Clothing | E12: West | F12: 6 | G12: 318.88 | H12: 0.02 | I12: COD | J12: 7 | K12: 1.4 | L12: 1875.01
A13: 10012 | B13: 44573 | C13: 1214 | D13: Electronics | E13: West | F13: 3 | G13: 384.71 | H13: 0.14 | I13: COD | J13: 11 | K13: 1.9 | L13: 992.55
... A5001: 15000 | B5001: 49561 | C5001: 1214 | D5001: Home | E5001: East | F5001: 7 | G5001: 231.58 | H5001: 0.34 | I5001: COD | J5001: 5 | K5001: 3.9 | L5001: 1069.9

Sheet Data_Quality
A1: Check | B1: Column | C1: Result | D1: Status
A2: Total Records | B2: All | C2: 5000 | D2: PASS
A3: total Columns | B3: All | C3: 12 | D3: PASS
A4: Missing Values | B4: All | C4: 0 | D4: PASS
A5: Duplicate Order IDs | B5: oeder_id | C5: 0 | D5: PASS
A6: Unique Customers | B6: customer_id | C6: 989 | D6: INFO
A7: Minimum | B7: quantity | C7: 1 | D7: PASS
A8: Maximum | B8: quantity | C8: 7 | D8: PASS
A9: Minimum | B9: unit_price | C9: 15.15 | D9: PASS
A10: Maximum | B10: unit_price | C10: 599.96 | D10: PASS
A11: Minimum | B11: discount | C11: 0 | D11: PASS
A12: Maximum | B12: discount | C12: 0.35 | D12: PASS
A13: Minimum | B13: delivery_days | C13: 1 | D13: PASS
... A18: Maximum | B18: Revenue | C18: 4119.33 | D18: PASS
A19: Revenue Validation | B19: Revenue | C19: 4908 OK / 92 ±0.01 | D19: PASS
A20: Date Range | B20: order_data | C20: 2022-01-01 to 2035-09-09 | D20: PASS
A21: Unique Categorirs | B21: product_ Category | C21: 4 | D21: PASS
A22: Unique Regions | B22: region | C22: 4 | D22: PASS
A23: Unique Payment Methods | B23: payment_method | C23: 3 | D23: PASS

Sheet Clean_Data
A1: order_id | B1: order_date | C1: customer_id | D1: product_category | E1: region | F1: quantity | G1: unit_price | H1: discount | I1: payment_method | J1: delivery_days | K1: customer_rating | L1: revenue
A2: 10001 | B2: 44562 | C2: 1102 | D2: Beauty | E2: South | F2: 7 | G2: 373.65 | H2: 0.28 | I2: Wallet | J2: 10 | K2: 4.7 | L2: 1883.2
A3: 10002 | B3: 44563 | C3: 1435 | D3: Clothing | E3: South | F3: 7 | G3: 47.74 | H3: 0.09 | I3: Card | J3: 6 | K3: 3.9 | L3: 304.1
A4: 10003 | B4: 44564 | C4: 1860 | D4: Beauty | E4: East | F4: 3 | G4: 311.28 | H4: 0.31 | I4: COD | J4: 6 | K4: 2.5 | L4: 644.35
A5: 10004 | B5: 44565 | C5: 1270 | D5: Electronics | E5: West | F5: 5 | G5: 524.47 | H5: 0.02 | I5: Wallet | J5: 6 | K5: 1.6 | L5: 2569.9
A6: 10005 | B6: 44566 | C6: 1106 | D6: Clothing | E6: West | F6: 5 | G6: 139.87 | H6: 0.33 | I6: Wallet | J6: 4 | K6: 4.9 | L6: 468.56
A7: 10006 | B7: 44567 | C7: 1071 | D7: Electronics | E7: West | F7: 2 | G7: 264.44 | H7: 0.2 | I7: Card | J7: 3 | K7: 3.3 | L7: 423.1
A8: 10007 | B8: 44568 | C8: 1700 | D8: Clothing | E8: South | F8: 6 | G8: 564.6 | H8: 0.23 | I8: Card | J8: 1 | K8: 1.8 | L8: 2608.45
A9: 10008 | B9: 44569 | C9: 1020 | D9: Beauty | E9: North | F9: 6 | G9: 265.71 | H9: 0.13 | I9: Card | J9: 2 | K9: 3.7 | L9: 1387.01
A10: 10009 | B10: 44570 | C10: 1614 | D10: Clothing | E10: South | F10: 6 | G10: 224.65 | H10: 0.27 | I10: Card | J10: 2 | K10: 1.4 | L10: 983.97
A11: 10010 | B11: 44571 | C11: 1121 | D11: Clothing | E11: West | F11: 4 | G11: 272.71 | H11: 0.06 | I11: Card | J11: 10 | K11: 4.5 | L11: 1025.39
A12: 10011 | B12: 44572 | C12: 1466 | D12: Clothing | E12: West | F12: 6 | G12: 318.88 | H12: 0.02 | I12: COD | J12: 7 | K12: 1.4 | L12: 1875.01
A13: 10012 | B13: 44573 | C13: 1214 | D13: Electronics | E13: West | F13: 3 | G13: 384.71 | H13: 0.14 | I13: COD | J13: 11 | K13: 1.9 | L13: 992.55
... A5001: 15000 | B5001: 49561 | C5001: 1214 | D5001: Home | E5001: East | F5001: 7 | G5001: 231.58 | H5001: 0.34 | I5001: COD | J5001: 5 | K5001: 3.9 | L5001: 1069.9

Sheet Validation
A1: calculated_revenue | B1: revenue_check | C1: revenue_difference | E1: Validation Summary | F1: Resuit | H1: Outlier Analysis
A2: =Clean_Data!F2*Clean_Data!G2*(1-Clean_Data!H2) -> 1883.196 | B2: =IF(ROUND(A2,2)=ROUND(Clean_Data!L2,2),"OK","ERROR") -> OK | C2: =ROUND(A2-Clean_Data!L2,2) -> 0 | E2: OK Count | F2: =COUNTIF(B2:B5001,"OK") -> 4908 | H2: Column | I2: Q1 | J2: Q3 | K2: IQR | L2: Lower Bound | M2: Upper Bound | N2: Outliers
A3: =Clean_Data!F3*Clean_Data!G3*(1-Clean_Data!H3) -> 304.1038 | B3: =IF(ROUND(A3,2)=ROUND(Clean_Data!L3,2),"OK","ERROR") -> OK | C3: =ROUND(A3-Clean_Data!L3,2) -> 0 | E3: ERROR Count | F3: =COUNTIF(B2:B5001,"ERROR") -> 92 | H3: unit_price | I3: =_xlfn.QUARTILE.INC(Clean_Data!G2:G5001,1) -> 161.895 | J3: =_xlfn.QUARTILE.INC(Clean_Data!G2:G5001,3) -> 455.5575 | K3: =J3-I3 -> 293.6625 | L3: =I3-1.5*K3 -> -278.59875 | M3: =J3+1.5*K3 -> 896.05125 | N3: =COUNTIF(Clean_Data!G2:G5001,">"&M3)+COUNTIF(Clean_Data!G2:G5001,"<"&L3) -> 0
A4: =Clean_Data!F4*Clean_Data!G4*(1-Clean_Data!H4) -> 644.3496 | B4: =IF(ROUND(A4,2)=ROUND(Clean_Data!L4,2),"OK","ERROR") -> OK | C4: =ROUND(A4-Clean_Data!L4,2) -> 0 | E4: Max Difference | F4: =MAX(C2:C5001) -> 0.01 | H4: revenue | I4: =_xlfn.QUARTILE.INC(Clean_Data!L2:L5001,1) -> 354.5275 | J4: =_xlfn.QUARTILE.INC(Clean_Data!L2:L5001,3) -> 1515.69 | K4: =J4-I4 -> 1161.1625 | L4: =I4-1.5*K4 -> -1387.2163 | M4: =J4+1.5*K4 -> 3257.4338 | N4: =COUNTIF(Clean_Data!L2:L5001,">"&M4)+COUNTIF(Clean_Data!L2:L5001,"<"&L4) -> 67
A5: =Clean_Data!F5*Clean_Data!G5*(1-Clean_Data!H5) -> 2569.903 | B5: =IF(ROUND(A5,2)=ROUND(Clean_Data!L5,2),"OK","ERROR") -> OK | C5: =ROUND(A5-Clean_Data!L5,2) -> 0 | E5: Min Difference | F5: =MIN(C2:C5001) -> -0.01 | H5: delivery_days | I5: =_xlfn.QUARTILE.INC(Clean_Data!J2:J5001,1) -> 3 | J5: =_xlfn.QUARTILE.INC(Clean_Data!J2:J5001,3) -> 9 | K5: =J5-I5 -> 6 | L5: =I5-1.5*K5 -> -6 | M5: =J5+1.5*K5 -> 18 | N5: =COUNTIF(Clean_Data!J2:J5001,">"&M5)+COUNTIF(Clean_Data!J2:J5001,"<"&L5) -> 0
A6: =Clean_Data!F6*Clean_Data!G6*(1-Clean_Data!H6) -> 468.5645 | B6: =IF(ROUND(A6,2)=ROUND(Clean_Data!L6,2),"OK","ERROR") -> OK | C6: =ROUND(A6-Clean_Data!L6,2) -> 0 | H6: customer_rating | I6: =_xlfn.QUARTILE.INC(Clean_Data!K2:K5001,1) -> 2 | J6: =_xlfn.QUARTILE.INC(Clean_Data!K2:K5001,3) -> 4 | K6: =J6-I6 -> 2 | L6: =I6-1.5*K6 -> -1 | M6: =J6+1.5*K6 -> 7 | N6: =COUNTIF(Clean_Data!K2:K5001,">"&M6)+COUNTIF(Clean_Data!K2:K5001,"<"&L6) -> 0
A7: =Clean_Data!F7*Clean_Data!G7*(1-Clean_Data!H7) -> 423.104 | B7: =IF(ROUND(A7,2)=ROUND(Clean_Data!L7,2),"OK","ERROR") -> OK | C7: =ROUND(A7-Clean_Data!L7,2) -> 0 | H7: discount | I7: =_xlfn.QUARTILE.INC(Clean_Data!H2:H5001,1) -> 0.09 | J7: =_xlfn.QUARTILE.INC(Clean_Data!H2:H5001,3) -> 0.27 | K7: =J7-I7 -> 0.18 | L7: =I7-1.5*K7 -> -0.18 | M7: =J7+1.5*K7 -> 0.54 | N7: =COUNTIF(Clean_Data!H2:H5001,">"&M7)+COUNTIF(Clean_Data!H2:H5001,"<"&L7) -> 0
A8: =Clean_Data!F8*Clean_Data!G8*(1-Clean_Data!H8) -> 2608.452 | B8: =IF(ROUND(A8,2)=ROUND(Clean_Data!L8,2),"OK","ERROR") -> OK | C8: =ROUND(A8-Clean_Data!L8,2) -> 0
A9: =Clean_Data!F9*Clean_Data!G9*(1-Clean_Data!H9) -> 1387.0062 | B9: =IF(ROUND(A9,2)=ROUND(Clean_Data!L9,2),"OK","ERROR") -> OK | C9: =ROUND(A9-Clean_Data!L9,2) -> 0
A10: =Clean_Data!F10*Clean_Data!G10*(1-Clean_Data!H10) -> 983.967 | B10: =IF(ROUND(A10,2)=ROUND(Clean_Data!L10,2),"OK","ERROR") -> OK | C10: =ROUND(A10-Clean_Data!L10,2) -> 0
A11: =Clean_Data!F11*Clean_Data!G11*(1-Clean_Data!H11) -> 1025.3896 | B11: =IF(ROUND(A11,2)=ROUND(Clean_Data!L11,2),"OK","ERROR") -> OK | C11: =ROUND(A11-Clean_Data!L11,2) -> 0
A12: =Clean_Data!F12*Clean_Data!G12*(1-Clean_Data!H12) -> 1875.0144 | B12: =IF(ROUND(A12,2)=ROUND(Clean_Data!L12,2),"OK","ERROR") -> OK | C12: =ROUND(A12-Clean_Data!L12,2) -> 0
A13: =Clean_Data!F13*Clean_Data!G13*(1-Clean_Data!H13) -> 992.5518 | B13: =IF(ROUND(A13,2)=ROUND(Clean_Data!L13,2),"OK","ERROR") -> OK | C13: =ROUND(A13-Clean_Data!L13,2) -> 0
A14: =Clean_Data!F14*Clean_Data!G14*(1-Clean_Data!H14) -> 2368.709 | B14: =IF(ROUND(A14,2)=ROUND(Clean_Data!L14,2),"OK","ERROR") -> OK | C14: =ROUND(A14-Clean_Data!L14,2) -> 0
A15: =Clean_Data!F15*Clean_Data!G15*(1-Clean_Data!H15) -> 1447.7064 | B15: =IF(ROUND(A15,2)=ROUND(Clean_Data!L15,2),"OK","ERROR") -> OK | C15: =ROUND(A15-Clean_Data!L15,2) -> 0
A16: =Clean_Data!F16*Clean_Data!G16*(1-Clean_Data!H16) -> 1617.7944 | B16: =IF(ROUND(A16,2)=ROUND(Clean_Data!L16,2),"OK","ERROR") -> OK | C16: =ROUND(A16-Clean_Data!L16,2) -> 0
A17: =Clean_Data!F17*Clean_Data!G17*(1-Clean_Data!H17) -> 523.568 | B17: =IF(ROUND(A17,2)=ROUND(Clean_Data!L17,2),"OK","ERROR") -> OK | C17: =ROUND(A17-Clean_Data!L17,2) -> 0
A18: =Clean_Data!F18*Clean_Data!G18*(1-Clean_Data!H18) -> 607.0785 | B18: =IF(ROUND(A18,2)=ROUND(Clean_Data!L18,2),"OK","ERROR") -> OK | C18: =ROUND(A18-Clean_Data!L18,2) -> 0
A19: =Clean_Data!F19*Clean_Data!G19*(1-Clean_Data!H19) -> 1987.503 | B19: =IF(ROUND(A19,2)=ROUND(Clean_Data!L19,2),"OK","ERROR") -> OK | C19: =ROUND(A19-Clean_Data!L19,2) -> 0
... A5001: =Clean_Data!F5001*Clean_Data!G5001*(1-Clean_Data!H5001) -> 1069.8996 | B5001: =IF(ROUND(A5001,2)=ROUND(Clean_Data!L5001,2),"OK","ERROR") -> OK | C5001: =ROUND(A5001-Clean_Data!L5001,2) -> 0
A5002: =Clean_Data!F5002*Clean_Data!G5002*(1-Clean_Data!H5002) -> 0
A5003: =Clean_Data!F5003*Clean_Data!G5003*(1-Clean_Data!H5003) -> 0
A5004: =Clean_Data!F5004*Clean_Data!G5004*(1-Clean_Data!H5004) -> 0
A5005: =Clean_Data!F5005*Clean_Data!G5005*(1-Clean_Data!H5005) -> 0
A5006: =Clean_Data!F5006*Clean_Data!G5006*(1-Clean_Data!H5006) -> 0
A5007: =Clean_Data!F5007*Clean_Data!G5007*(1-Clean_Data!H5007) -> 0
A5008: =Clean_Data!F5008*Clean_Data!G5008*(1-Clean_Data!H5008) -> 0
A5009: =Clean_Data!F5009*Clean_Data!G5009*(1-Clean_Data!H5009) -> 0
A5010: =Clean_Data!F5010*Clean_Data!G5010*(1-Clean_Data!H5010) -> 0
A5011: =Clean_Data!F5011*Clean_Data!G5011*(1-Clean_Data!H5011) -> 0

Sheet Analysis
A1: Row Labels | B1: Sum of revenue
A2: Beauty | B2: 765860.88
A3: Clothing | B3: 1531931.7
A4: Electronics | B4: 1829899.2
A5: Home | B5: 982083.92
A6: Grand Total | B6: 5109775.7
A8: Row Labels | B8: Sum of revenue
A9: Card | B9: 2366248.2
A10: COD | B10: 1788408.4
A11: Wallet | B11: 955119.1
A12: Grand Total | B12: 5109775.7
A14: Delivery Days | B14: Average Rating
A15: 1 | B15: 2.9886364
A16: 2 | B16: 2.9358491
A17: 3 | B17: 2.9314634
A18: 4 | B18: 3.071308
A19: 5 | B19: 3.0443099
A20: 6 | B20: 2.9636175
A21: 7 | B21: 3.0246316
A22: 8 | B22: 2.9855011
A23: 9 | B23: 2.9538462
A24: 10 | B24: 2.9245935
A25: 11 | B25: 2.890364
A27: Row Labels | B27: Sum of revenue
A28: East | B28: 1236044.2
A29: North | B29: 1281508.5
A30: South | B30: 1246640.9
A31: West | B31: 1345582.2
A32: Grand Total | B32: 5109775.7
A34: Row Labels | B34: Sum of revenue
A35: 2022 | B35: 371824.3
A36: 2023 | B36: 365915.79
A37: 2024 | B37: 363209.13
A38: 2025 | B38: 349802.33
A39: 2026 | B39: 386369.69
A40: 2027 | B40: 386151.91
A41: 2028 | B41: 376844.8
A42: 2029 | B42: 359239.24
A43: 2030 | B43: 387884.46
A44: 2031 | B44: 365250.83
...

Sheet Dashboard
A1: SALES & CUSTOMER ANALYSIS DSHBOARD
A4: TOTAL ORDERS | C4: TOTAL REVENUE | E4: AVG. REVENUE / ORDER
A5: 5000 | C5: 5109775.7 | E5: 1021.96
